File: Mutation_burden_plots/sigfit_output_wComp4_oct2024_old/PD42761a_lo0003_contrib.txt
PD42761a_lo0003
SBS5	0.114104820951943
SBS13	0.0728471987720254
SBS18	0.0895115473914014
SBS40	0.309192557033775
Sig4	0.0955952952511888
SBS9	0.154187505430465
SBS1	0.138877421691993
SBS2	0.0256836534772087