File: Mutation_burden_plots/sigfit_output_wComp4_oct2024_old/PD42768a_lo0051_contrib.txt
PD42768a_lo0051
SBS5	0.143548919339082
SBS2	0.0355862008429086
SBS13	0.0160326342312874
SBS8	0.214017760862183
SBS18	0.0671004316202825
SBS40	0.13851921484338
Sig4	0.0678853781958833
SBS9	0.0717848650950463
SBS1	0.245524594969947