File: Mutation_burden_plots/sigfit_output_wComp4_oct2024_old/PD42767a_lo0006_contrib.txt
PD42767a_lo0006
SBS5	0.230316664178852
SBS8	0.0823202412718529
SBS18	0.0853091574307352
SBS40	0.147417666582133
Sig4	0.148260912167371
SBS9	0.104074589804644
SBS1	0.140419194615622
SBS2	0.0114931318427682
SBS13	0.0503884421060212