File: Mutation_burden_plots/sigfit_output_wComp4_oct2024_old/PD42767a_duct1a_contrib.txt
PD42767a_duct1a
SBS5	0.311320918537835
SBS8	0.1049403985558
SBS40	0.105744463779557
Sig4	0.059460890532746
SBS9	0.213936413729881
SBS1	0.16223336114596
SBS2	0.0209890316500301
SBS13	0.0213745220681914