File: Mutation_burden_plots/sigfit_output_wComp4_oct2024_old/PD42767a_CD20_1b_contrib.txt
PD42767a_CD20_1b
SBS5	0.0568567294110198
SBS8	0.0671395715616789
SBS18	0.116664953146401
SBS40	0.170226931311177
Sig4	0.110613399124488
SBS9	0.223583236165169
SBS1	0.143990426390956
SBS17b	0.11092475288911