File: Mutation_burden_plots/sigfit_output_wComp4_oct2024_old/PD42772a_lo0118_contrib.txt
PD42772a_lo0118
SBS5	0.294104477341715
SBS13	0.0710941062766363
SBS8	0.0740733607268119
SBS18	0.100096383468804
SBS40	0.180366616630404
Sig4	0.0681662927709776
SBS9	0.0736103593541574
SBS1	0.12825942489293
SBS2	0.0102289785375637