File: Mutation_burden_plots/sigfit_output_wComp4_oct2024_old/PD42767a_gland9_contrib.txt
PD42767a_gland9
SBS5	0.310365936676285
SBS8	0.07628778125477
SBS18	0.0812070481315346
SBS40	0.246614264672875
Sig4	0.0650621507584658
SBS9	0.0697930672990574
SBS1	0.102935653371153
SBS17b	0.0477340978358594