File: Mutation_burden_plots/sigfit_output_wComp4_oct2024_old/PD42772a_lo0123_contrib.txt
PD42772a_lo0123
SBS5	0.145087220912303
SBS13	0.0509365180042233
SBS8	0.0455958778390027
SBS18	0.148919924642351
SBS40	0.211571144680376
Sig4	0.08536681824321
SBS9	0.122140494441393
SBS1	0.157701857375167
SBS2	0.0326801438619729