File: Mutation_burden_plots/sigfit_output_wComp4_oct2024_old/PD42768a_lo0081_contrib.txt
PD42768a_lo0081
SBS5	0.0958156984963263
SBS8	0.0883957997573779
SBS40	0.198883266546962
Sig4	0.21563123226901
SBS9	0.161015994931477
SBS1	0.178836406736291
SBS2	0.0424770067841607
SBS13	0.0189445944783952