File: Mutation_burden_plots/sigfit_output_wComp4_oct2024_old/PD42767a_lo0010_contrib.txt
PD42767a_lo0010
SBS5	0.150305756714061
SBS18	0.0733695271363652
SBS40	0.177325375853509
Sig4	0.0690314485065332
SBS9	0.245805531910689
SBS1	0.225619659340326
SBS2	0.0205557964098671
SBS13	0.0379869041286485