File: Mutation_burden_plots/sigfit_output_wComp4_oct2024_old/PD42768a_duct1_contrib.txt
PD42768a_duct1
SBS5	0.0963588975122474
SBS18	0.158380582116646
SBS40	0.152825871140883
Sig4	0.181042796781628
SBS9	0.125969326649752
SBS1	0.241605059801655
SBS2	0.0305835744041551
SBS13	0.0132338915930335