File: Mutation_burden_plots/sigfit_output_wComp4_oct2024_old/PD42767a_CD38_1_contrib.txt
PD42767a_CD38_1
SBS5	0.0910913413486062
SBS8	0.148955423485363
SBS18	0.0987719447404967
SBS40	0.079057386556382
Sig4	0.0914758909878611
SBS9	0.273541543511246
SBS1	0.11663382384845
SBS17b	0.100472645521595