File: Mutation_burden_plots/sigfit_output_wComp4_oct2024_old/PD42766a_lo0049_contrib.txt
PD42766a_lo0049
SBS5	0.139141224079483
SBS18	0.167451518619464
SBS40	0.165812554985034
Sig4	0.13530686748378
SBS9	0.173367995331193
SBS1	0.147750544835735
SBS2	0.0422787743879506
SBS13	0.0288905202773596