File: Mutation_burden_plots/sigfit_output_wComp4_oct2024_old/PD42760a_duct15_contrib.txt
PD42760a_duct15
SBS5	0.138986582184617
SBS18	0.108081344736878
SBS40	0.137654371602893
Sig4	0.33715470714854
SBS9	0.107250551475454
SBS1	0.0991614473794705
SBS2	0.0463288612749101
SBS13	0.0253821341972371