File: Mutation_burden_plots/sigfit_output_wComp4_oct2024_old/PD42772a_lo0126_contrib.txt
PD42772a_lo0126
SBS5	0.226181419671151
SBS2	0.0263223975066002
SBS13	0.0294350493598553
SBS8	0.0876737197156634
SBS18	0.0624773217253281
SBS40	0.254185365340664
Sig4	0.060129245957369
SBS9	0.088466798327211
SBS1	0.109565711665065
SBS17b	0.0555629707310925