File: Mutation_burden_plots/sigfit_output_wComp4_oct2024_old/PD42765a_lo0016_contrib.txt
PD42765a_lo0016
SBS5	0.095612178852368
SBS2	0.0542207462534987
SBS13	0.285899799292949
SBS8	0.121594450919625
SBS40	0.0894818701783121
Sig4	0.0472116960211287
SBS9	0.160073659319774
SBS1	0.145905599162344