File: Mutation_burden_plots/sigfit_output_wComp4_oct2024_old/PD42767a_duct7_contrib.txt
PD42767a_duct7
SBS5	0.219948512897204
SBS8	0.102752480817568
SBS18	0.0644756314991079
SBS40	0.163274954463286
Sig4	0.0765536289242828
SBS9	0.226718790330093
SBS1	0.0844492834732796
SBS17b	0.0618267175951783