File: Mutation_burden_plots/sigfit_output_wComp4_oct2024_old/PD42767a_lo0004_contrib.txt
PD42767a_lo0004
SBS5	0.0902476620400051
SBS8	0.0485947359698579
SBS18	0.109163710001708
SBS40	0.143102772362322
Sig4	0.314108595399764
SBS9	0.0732226561537508
SBS1	0.16011745656229
SBS2	0.0425719060355314
SBS13	0.0188705054747707