File: Mutation_burden_plots/sigfit_output_wComp4_oct2024_old/PD42773a_lo0060_contrib.txt
PD42773a_lo0060
SBS5	0.242585627519396
SBS13	0.0651086710087105
SBS8	0.0556614357362996
SBS40	0.0868814873723579
Sig4	0.374784217257078
SBS9	0.0595642459880741
SBS1	0.103713390890431
SBS2	0.0117009242276531