File: Mutation_burden_plots/sigfit_output_wComp4_oct2024_old/PD42770a_CD20-2_contrib.txt
PD42770a_CD20-2
SBS5	0.105600362791336
SBS2	0.121903709057529
SBS18	0.132096979994707
SBS40	0.110559978375814
Sig4	0.334000916374793
SBS9	0.0876203588319668
SBS1	0.0996838492246356
SBS13	0.00853384534921907