File: Mutation_burden_plots/sigfit_output_wComp4_oct2024_old/PD42767a_lo0009_contrib.txt
PD42767a_lo0009
SBS5	0.078293902413078
SBS18	0.0885575472743462
SBS40	0.115599433387999
Sig4	0.248954143606301
SBS9	0.160855168014464
SBS1	0.246182386651482
SBS2	0.0414163584322393
SBS13	0.0201410602200906