File: Mutation_burden_plots/sigfit_output_wComp4_oct2024_old/PD42760a_duct13_contrib.txt
PD42760a_duct13
SBS5	0.337724489644744
SBS2	0.0753581769781876
SBS13	0.0146108264496809
SBS8	0.0935293930025378
SBS18	0.0677517159136917
SBS40	0.0907714583065924
Sig4	0.0526236335169475
SBS9	0.124949435679679
SBS1	0.142680870507939