File: Mutation_burden_plots/sigfit_output_wComp4_oct2024_old/PD45530a_lo0027_contrib.txt
PD45530a_lo0027
SBS5	0.339646579881291
SBS8	0.0597343771977293
SBS40	0.119732174315498
Sig4	0.209109951189202
SBS9	0.136238107624251
SBS1	0.0829055281574727
SBS2	0.0247750669369878
SBS13	0.027858214697569