File: Mutation_burden_plots/sigfit_output_wComp4_oct2024_old/PD45530a_lo0025_contrib.txt
PD45530a_lo0025
SBS5	0.269708801992079
SBS2	0.119526492555425
SBS13	0.151328191622343
SBS18	0.0495115035876925
SBS40	0.156789981565798
Sig4	0.112560538274134
SBS9	0.077972123236447
SBS1	0.0626023671660808