File: Mutation_burden_plots/sigfit_output_wComp4_oct2024_old/PD45527a_lo0024_contrib.txt
PD45527a_lo0024
SBS5	0.166834551864436
SBS8	0.0918726562631965
SBS18	0.150942410179992
SBS40	0.16430999989816
Sig4	0.144144665978259
SBS9	0.116260073337164
SBS1	0.105285982295367
SBS2	0.0186225389311977
SBS13	0.0417271212522272